Workbook

Sheet Test_Case
A1: Project Name | B1: OrangeHRM Manual Testing
A2: Reference Document | B2: OHM-RA-2026 | OHM-TP-2026 | OHM-TS-2026
A3: Created By | B3: Nguyễn Long Vũ
A4: Date of creation | B4: 46183
A5: Date of reivew | B5: 46183
A7: # | B7: Test Case ID | C7: Module | D7: Test Objective | E7: Type | F7: Priority | G7: Precondition | H7: Steps | I7: Test Data | J7: Expected Result | K7: Actual Result | L7: Status | M7: Bug ID | N7: Notes
A8: 1 | B8: TC_001 | C8: Login | D8: Successful login with Admin credentials(admin/Admin123) | E8: Positive | F8: High | G8: 1.Browser is open 2 . User is on the OrangeHRM login page at https://opensource-demo.orangehrmlive.com | H8: 1. Navigate to https://opensource-demo.orangehrmlive.com/ 2. Enter admin in Username fields 3.Enter Admin123 in Password fields 4.Click the login button | I8: admin admin123 | J8: User is redirected to the OrangeHRM Dashboard The top-right header displays 'Admin' (or the Admin display name). Left navigation menu is fully visible with all Admin modules. | K8: Login successful. Redirected to /dashboard/index. Full sidebar visible: Admin, PIM, Leave, Time, Recruitment, My Info, Performance, Dashboard, Directory, Maintenance, Claim, Buzz. Header shows "Admin" username with avatar. | L8: PASS
A9: 2 | B9: TC_002 | C9: Login | D9: Admin has created an ESS User account .Successful login with valid ESS User credentials | E9: Positive | F9: High | G9: 1.ESS User account created in Admin 2.Browser open at login page | H9: 1. Navigate to https://opensource-demo.orangehrmlive.com/ 2. Enter ESS User's in Username fields 3.Enter password in Password fileds 4.Click the login button 5.Observe the Dashboard and left navigation menu | I9: Username : testess Password : Test@1234 | J9: User is redirected to Dashboard. Left menu shows limited ESS options: Dashboard, My Info, Leave, Time, Performance, Directory, Buzz. Admin-only menus (Admin, PIM full access) are NOT visible. | K9: Login successful. Redirected to /dashboard/index. Limited sidebar visible — Admin module NOT shown. Header shows "testess" username. Dashboard widgets visible with limited data. | L9: PASS
A10: 3 | B10: TC_003 | C10: Login | D10: Login fails with incorrect password | E10: Negative | F10: High | G10: 1.Browser open at login page | H10: 1. Navitage to https://opensource-demo.orangehrmlive.com/ 2. Enter Username : Admin 3.Enter password : wrongpass 4.Click the login button 5.Observe error message | I10: Username : Admin Password : wrongpass | J10: Error message displayrd : "Invaild credentials" User remains on login page No redirect occurs | K10: Error message displayed at top of form: "Invalid credentials". User remained on login page. No redirect occurred. | L10: PASS
A11: 4 | B11: TC_004 | C11: Login | D11: Login fails with incorrect username | E11: Negative | F11: High | G11: 1.Browser open at login page | H11: 1. Navitage to https://opensource-demo.orangehrmlive.com/ 2. Enter Username : wronguser 3.Enter password : admin123 4.Click the login button 5.Observe error message | I11: Username : wronguser Password : admin123 | J11: Error message displayed : "Invalid credentials" User remains on login page | K11: Error message displayed: "Invalid credentials". User remained on login page. No redirect occurred. Behavior identical to TC_003 — same error message for both wrong username and wrong password. | L11: PASS
A12: 5 | B12: TC_005 | C12: Login | D12: Login fails when both fields are empty | E12: Negative | F12: High | G12: 1.Browser open at login page | H12: 1. Navitage to https://opensource-demo.orangehrmlive.com/ 2. Leave username empty 3.Leave password empty 4.Click the login button 5.Observe error | I12: Username : (empty) Password : (empty) | J12: Validation message appear below both fields "Required".user stays on login page | K12: Validation error appeared below Username: "Required". Validation error appeared below Password: "Required". Both fields highlighted in red. User stayed on login page. No redirect. | L12: PASS
A13: 6 | B13: TC_006 | C13: Login | D13: Login fails when username fields is empty | E13: Negative | F13: Medium | G13: 1.Browser open at login page | H13: 1. Navitage to https://opensource-demo.orangehrmlive.com/ 2. Leave username fields empty 3.Enter password : admin123 4.Click the login button 5.Observe error | I13: Username : (empty) Password : admin123 | J13: Validation message appear below username fields "Required".user stays on login page | K13: Validation error appeared below Username: "Required". Password field accepted input normally. User stayed on login page. System validates Username field first before Password. | L13: PASS
A14: 7 | B14: TC_007 | C14: Login | D14: Login fails when password fields is empty | E14: Negative | F14: Medium | G14: 1.Browser open at login page | H14: 1. Navitage to https://opensource-demo.orangehrmlive.com/ 2. Enter Username : Admin 3.Leave password fields empty 4.Click the login button 5.Observe error | I14: Username : Admin Password : (empty) | J14: Validation message appear below password fields "Required".user stays on login page | K14: Validation error appeared below Password: "Required". Username field accepted "Admin" correctly. User stayed on login page. | L14: PASS
A15: 8 | B15: TC_008 | C15: Login | D15: Login with username in ALL CAPS is rejected (case sensitivity) | E15: Boundary | F15: Medium | G15: 1.Browser open at login page | H15: 1. Navitage to https://opensource-demo.orangehrmlive.com/ 2. Enter Username : ADMIN 3.Enter password : admin123 4.Click the login button 5.Observe result | I15: Username : ADMIN Password : admin123 | J15: Login fails with "Invalid credentials" . System is case-sensitive "ADMIN" not "admin" | K15: Login successful with username "ADMIN" (all caps). System is NOT case-sensitive for username field. "ADMIN" accepted same as "Admin". No error message displayed. | L15: FAILS | M15: Bug ID: #1 ( https://github.com/zues5sne/orangehrm-manual-testing/issues/1 )
A16: 9 | B16: TC_009 | C16: Login | D16: Login with leading/trailing spaces in username field | E16: Boundary | F16: Medium | G16: 1.Browser open at login page | H16: 1.Enter usname " Admin " (with spaces before/after) 2.Enter password : admin123 3.Click Login button 4.Observe result | I16: Username : " Admin " Password : admin123 | J16: System may trim spaces (login succeeds) or reject (login fails) Document actual behavior | K16: Login failed with username " admin " (leading/trailing spaces). Error: "Invalid credentials". System does NOT trim spaces — " admin " ≠ "Admin". Username field is space-sensitive. | L16: PASS
A17: 10 | B17: TC_010 | C17: Login | D17: Password field mask characters | E17: Positive | F17: Medium | G17: 1.Browser open at login page | H17: 1.Click password field 2.Type any characters 3.Observe how characters are displayed | I17: Password : anyvalue123 | J17: Characters appear as dots (•••) or asterisks. Plain text is never visible at any time during input. | K17: Typed "anyvalue123" into Password field. All characters displayed as dots (•••). Plain text never visible at any point during input. Password masking works correctly. | L17: PASS
A18: 11 | B18: TC_011 | C18: Login | D18: Forgot password link redirects to reset page | E18: Positive | F18: Medium | G18: 1.Browser open at login page | H18: 1.Click "Forgot your Password?" link below login form 2. Observe navigation | J18: Page redirects to password reset / recovery page . A form to enter email/password is displayed | K18: Clicked "Forgot your password?" link. Redirected to /web/index.php/auth/requestPasswordResetCode. Page shows form with field: "Username". User can enter username to receive reset instructions. | L18: PASS
A19: 12 | B19: TC_012 | C19: Login | D19: Browser Back button cannot restore session after logout | E19: Negative | F19: High | G19: 1.User is logged in as Admin on DashBoard | H19: 1.Click username in top right - Logout 2.Confirm redirect to login page 3.Press browser Back button 4.Observe result | J19: Browser does not navigate back to DashBoard .Login page remains displayed or user redirected to Login . Session is fully invalidated | K19: Clicked Logout → redirected to Login page. Pressed browser Back button. Dashboard loaded successfully WITHOUT re-authentication. User can access protected pages after logout via Back button. Session NOT fully invalidated on logout. | L19: FAILS | M19: Bug ID: #2 ( https://github.com/zues5sne/orangehrm-manual-testing/issues/2 )
A20: 13 | B20: TC_013 | C20: PIM | D20: Admin adds new employee with all required fields | E20: Positive | F20: High | G20: 1.Logged in as Admin.On PIM 2.Employee List Page | H20: 1.Click add button 2.Enter first name : Test 3.Enter Last name : Employee 4.Note auto-generated Employee ID 5.Click Save 6.Observe result | I20: First name : Test Last name : Employee Employee ID : ( auto ) | J20: New employee created successfully . Success message shown . Employee appears in Employee List .Employee ID auto generated by system | K20: Employee "Test Employee" created successfully. Success message shown. Appears in Employee List. | L20: PASS | N20: System showed error: "Employee Id already exists". Manually changed ID to unique value. Clicked Save — employee created successfully. Success message displayed. Employee appears in Employee List.
A21: 14 | B21: TC_014 | C21: PIM | D21: Admin cannot add employee without First Name | E21: Negative | F21: High | G21: 1.Logged in as Admin.On Add Employee page | H21: 1.Leave First Name empty 2.Enter Last name : Employee 3.Click save 4.Observe validation | I21: First name : (empty) Last name : Employee Employee ID : ( auto ) | J21: Error message shown on First Name field : "Required" . Employee not created .System stays on Add Employee page | K21: Validation error: "Required" below First Name field. Employee not created. | L21: PASS
A22: 15 | B22: TC_015 | C22: PIM | D22: Admin cannot add employee without Last Name | E22: Negative | F22: High | G22: 1.Logged in as Admin.On Add Employee page | H22: 1.Leave First Name : Test 2.Enter Last name : (Empty) 3.Click save 4.Observe validation | I22: First name : test Last name : (empty) Employee ID : ( auto ) | J22: Error message shown on Last Name field : "Required" . Employee not created .System stays on Add Employee page | K22: Validation error: "Required" below Last Name field. Employee not created. | L22: PASS
A23: 16 | B23: TC_016 | C23: PIM | D23: Employee ID is auto generated when Admin adds new employee | E23: Positive | F23: High | G23: 1.Logged in as Admin.On Add Employee page | H23: 1.Open Add Employee form 2.Observe Employee ID field before saving 3.Save employee 4.Verify ID signed | J23: Employee field ID is pre-filled by system automatically . Value is unique and sequential .Can not be left blank by design | K23: Employee ID auto-generated as "0395". Filled all required fields and clicked Save. Error shown: "Employee Id already exists". Verified ID 0395 belongs to another employee. System has save-time validation but auto-generation does not check existing IDs. User must manually find and enter a unique ID. | L23: FAILS | M23: Bug ID: #3 ( https://github.com/zues5sne/orangehrm-manual-testing/issues/3 )
A24: 17 | B24: TC_017 | C24: PIM | D24: Admin edits existing employee personal details | E24: Positive | F24: High | G24: 1.Logged in as Admin. Test employee exists in system. | H24: 1. Go to PIM > Employee List 2. Click on test employee name 3. Go to Personal Details tab 4. Change Nationality field 5. Click Save 6. Reload page and verify | I24: Employee: Test Employee Nationality: change to any other value | J24: Changes saved successfully. Success toast notification shown. Updated value persists after page reload. | K24: Nationality updated to "Vietnamese". Success toast shown. Change persists after reload. | L24: PASS
A25: 18 | B25: TC_018 | C25: PIM | D25: Admin Deletes an employee from the System | E25: Positive | F25: High | G25: 1.Logged in as Admin. At least one non-critical test employee exists. | H25: 1. Go to PIM > Employee List 2. Select checkbox next to test employee 3. Click Delete button 4. Confirm deletion in dialog 5. Verify employee removed | I25: Employee: Test Employee (created in TC_013) | J25: Employee deleted from system. No longer appears in Employee List. Searching for deleted employee returns no results. | K25: Confirmation dialog appeared. Employee deleted. No longer in Employee List. | L25: PASS
A26: 19 | B26: TC_019 | C26: PIM | D26: Admin searches employee by full name - exact match | E26: Positive | F26: Medium | G26: 1.Logged in as Admin. Multiple employees exist in System | H26: 1. Go to PIM > Employee List 2. Enter full employee name in search field 3. Click search 4.Observe result | I26: Search: exact full name of existing employee | J26: Search returns exactly the matching employee. No unrelated employees shown. Results display name, ID, job title. | K26: 1 result returned — "Test Employee". Exact match search working correctly. | L26: PASS
A27: 20 | B27: TC_020 | C27: PIM | D27: Admin searches employee by partial name - exact partial match check | E27: Positive | F27: Medium | G27: 1.Logged in as Admin. Multiple employees exist in System | H27: 1. Go to PIM > Employee List 2. Enter partial employee name in search field 3. Click search 4.Observe result | I27: Search: exact partial name of existing employee | J27: All employees whose names contain the search string are returned. Results are relevant and complete. | K27: All employees containing "Test" returned. Partial match working correctly. | L27: PASS
A28: 21 | B28: TC_021 | C28: PIM | D28: Admin searches employee by non-existent name | E28: Negative | F28: Medium | G28: 1.Logged in as Admin | H28: 1. Go to PIM > Employee List 2. Enter name that does not exist : "ccczzz" 3. Click search 4.Observe result | I28: Search: "ccczzz" | J28: Empty result displayed. Message shown: 'No Records Found' or equivalent. No error or crash occurs. | K28: No results returned. Message: "No Records Found". | L28: PASS
A29: 22 | B29: TC_022 | C29: PIM | D29: Uploads valid profile photo (JPG under 1MB) | E29: Positive | F29: Medium | G29: 1.Logged in as Admin .On employee profile page | H29: 1.Click on profile photo area 2.Select valid JPG file under 1MB 3.Confirm upload 4.Observe result | I29: File : Valid .JPG size < 1MB | J29: Photo uploaded and displayed on employee profile . Updated photo visible in header and profile page | K29: Photo uploaded successfully. Updated photo visible on profile and header. | L29: PASS
A30: 23 | B30: TC_023 | C30: PIM | D30: Uploads photo over 2MB - size limit check | E30: Boundary | F30: Medium | G30: Logged in as Admin. On employee profile page. Note: Exact limit unknown — testing to discover threshold. | H30: 1.Click on profile photo area 2.Select image file over 2MB 3.Attempt upload 4.Observe result | I30: File: image file > 2MB | J30: Upload fails for files >~1MB. Error message or silent failure observed. Exact size limit to be confirmed — document actual threshold found during testing. | K30: Selected image file over 2MB. Upload attempted — system rejected the file. Error message shown: file size exceeded limit. Profile photo unchanged. | L30: PASS | N30: Tested with 3.2MB file — rejected. 800KB file — accepted
A31: 24 | B31: TC_024 | C31: PIM | D31: ESS User views own Personal Details in My Info | E31: Positive | F31: High | G31: Logged in as ESS User (testess). | H31: 1. Click 'My Info' in sidebar 2. Navigate to Personal Details tab 3. Observe displayed information | I31: ESS user : testess | J31: Personal Details tab shows ESS user's own information only . Fields display correctly . No other employee's data visible | K31: Own personal details displayed correctly. No other employees' data visible. | L31: PASS
A32: 25 | B32: TC_025 | C32: PIM | D32: ESS User edits own Personal Details and save successfully | E32: Positive | F32: High | G32: Logged in as ESS User (testess). | H32: 1. Navigate to My Info > Contact Details 2. Update mobile number field 3. Click Save 4. Reload page and verify | I32: Mobile: update to any valid number(0901234567) | J32: Changes saved successfully. Success notification shown. Updated value persists after page reload. | K32: Mobile updated to 0901234567. Success toast shown. Change persists after reload. | L32: PASS
A33: 26 | B33: TC_026 | C33: PIM | D33: ESS User can not access another employee's profile | E33: Permission | F33: High | G33: Logged in as ESS User. Know the URL pattern for employee profiles. | H33: 1. As ESS User, note URL of own profile 2. Modify employee ID in URL to another employee's ID 3. Press Enter 4. Observe result | I33: URL: modify empNumber parameter to different employee ID | J33: Access denied. System redirects to own profile, Dashboard, or shows error message. ESS User cannot view other employees' data. | K33: Logged in as testess. Modified empNumber in URL to another employee's ID. System redirected to own profile / Access Denied shown. Other employee's data NOT accessible. Permission control working correctly. | L33: PASS
A34: 27 | B34: TC_027 | C34: PIM | D34: ESS User cannot add new employee | E34: Permission | F34: High | G34: Logged in as ESS User (testess). | H34: 1. Check sidebar menu — PIM module 2. Attempt to navigate to Add Employee URL directly 3. Observe result | I34: URL: /web/index.php/pim/addEmployee | J34: Add Employee option not visible in ESS User menu. Direct URL access redirects to Dashboard or shows Access Denied. | K34: Add Employee not available in ESS menu. Direct URL access redirected to Dashboard. | L34: PASS
A35: 28 | B35: TC_028 | C35: Leave | D35: Admin assigns Leave Entitlement to ESS User | E35: Positive | F35: High | G35: Logged in as Admin ESS User exist | H35: 1. Go to Leave > Entitlements > Add Entitlements 2. Select Employee: testess 3. Select Leave Type: Annual Leave 4. Set Days: 10 5. Set valid date range 6. Click Save | I35: Employee: testess Leave Type: Annual Leave Days: 10 | J35: Entitlement assigned successfully. ESS User now has 10 days Annual Leave balance. Visible in Leave > Entitlements list. | K35: Navigated to Leave > Entitlements > Add Entitlements. Selected Employee: testess. Selected Leave Type: Annual Leave, Days: 10. Clicked Save. Success message shown. Entitlement visible in Entitlements list. | L35: PASS
A36: 29 | B36: TC_029 | C36: Leave | D36: ESS User view balance Leave Entitlements | E36: Positive | F36: High | G36: Logged in as ESS User. Leave ment assigned (TC_028 completed). | H36: 1.Navigate to Leave > My entitlement 2.Observe leave balance table | I36: ESS User: testess | J36: Leave balance displayed correctly. Annual Leave shows 10 days (or remaining balance). All assigned leave types visible with correct numbers. | K36: Logged in as testess. Navigated to Leave > My Entitlements. Annual Leave balance shows 10 days available. All assigned leave types displayed correctly. | L36: PASS
A37: 30 | B37: TC_030 | C37: Leave | D37: ESS User applies Annual Leave for valid future date range | E37: Positive | F37: High | G37: Logged in as ESS User. Has leave balance. | H37: 1. Go to Leave > Apply 2. Select Leave Type: Annual Leave 3. Set From Date: tomorrow's date 4. Set To Date: 2 days from now 5. Enter Comment: 'Portfolio testing' 6. Click Apply | I37: Leave Type: Annual Leave From: tomorrow To: 2 days later Comment: Portfolio testing | J37: Leave request submitted. Status shows 'Pending'. Appears in My Leave list. Leave balance reduced by 2 days (or remains until approved — confirm behavior). | K37: Navigated to Leave > Apply. Selected Leave Type: Annual Leave. Set From: tomorrow, To: 2 days later. Entered Comment: Portfolio testing. Clicked Apply. Success message shown. Request appears in My Leave with status: Pending. | L37: PASS
A38: 31 | B38: TC_031 | C38: Leave | D38: ESS User applies leave with start date = today | E38: Boundary | F38: Medium | G38: Logged in as ESS User. Has leave balance. | H38: 1. Go to Leave > Apply 2. Select Leave Type: Annual Leave 3. Set From Date: today 4. Set To Date: today 5. Click Apply | I38: From Date : Today To Date : Today | J38: To be confirmed during testing: System either accepts same-day leave or shows validation. Document actual behavior — this is a boundary case. | K38: Validation error shown — cannot apply leave for current/past date | L38: PASS
A39: 32 | B39: TC_032 | C39: Leave | D39: Leave application when start date > end date | E39: Negative | F39: High | G39: Logged in as ESS User. On Apply Leave page. | H39: 1. Go to Leave > Apply 2. Select Leave Type: Annual Leave 3. Set From Date: next Friday 4. Set To Date: this Monday (before From Date) 5. Click Apply | I39: From Date : later date To Date : earlier date | J39: Validation error shown: date range is invalid. Application not submitted. User stays on Apply Leave page. | K39: Set From Date: next Friday. Set To Date: this Monday (before From Date). Clicked Apply. Validation error shown — invalid date range. Application not submitted. User stayed on Apply Leave page. | L39: PASS
A40: 33 | B40: TC_033 | C40: Leave | D40: Leave application when start date = end date (leave 1 day ) | E40: Boundary | F40: Medium | G40: Logged in as ESS User. Has leave balance. | H40: 1. Go to Leave > Apply 2. Set From Date and To Date to same future date 3. Click Apply | I40: From: future date To: same date | J40: 1-day leave request submitted successfully. Status shows 'Pending'. Leave balance reduced by 1 day (or upon approval). | K40: Set From Date and To Date to same future date. Clicked Apply. 1-day leave request submitted successfully. Status: Pending. 1 day deducted from balance preview. | L40: PASS
A41: 34 | B41: TC_034 | C41: Leave | D41: Leave spanning a weekend counts Sat/Sun as leave days | E41: Boundary | F41: Medium | G41: Logged in as ESS User. Has sufficient balance. | H41: 1. Apply leave from Friday to Monday (4 days including Sat/Sun) 2. Observe number of days counted 3. Check balance deduction | I41: From: Friday To: Monday (next week) | J41: System counts Saturday and Sunday as leave days. Total = 4 days deducted. This appears to be system default — working days config not set in demo environment. | K41: System calculates working days only. Leave from Friday to Monday = 2 days. Saturday and Sunday excluded from calculation. | L41: PASS
...

Sheet Summary_report
A1: TEST SUMMARY REPORT — OrangeHRM Manual Testing
A3: PROJECT INFORMATION
B4: Project | C4: OrangeHRM Manual Testing
B5: Website | C5: https://opensource-demo.orangehrmlive.com
B6: Tester | C6: Nguyễn Long Vũ
B7: Test Period | C7: 10/06/2026 — 20/06/2026
B8: Environment | C8: Chrome 124 / Windows 11
B9: Reference | C9: OHM-RA-2026 | OHM-TP-2026 | OHM-TS-2026
B10: Report Date | C10: 46193
A12: OVERALL TEST RESULTS
B13: Total TC | C13: Pass | D13: Fail | E13: Skip | F13: Pass Rate | G13: Overall
B14: =COUNTA(Test_Case!B8:B100) -> 50 | C14: =COUNTIF(Test_Case!L7:L100, "PASS") -> 47 | D14: =COUNTIF(Test_Case!L8:L100, "FAILS") -> 3 | E14: =COUNTIF(Test_Case!L7:L100, "Skip") -> 0 | F14: =C14/B14 -> 0.94 | G14: PASSED with 3 defects found
B16: Module | C16: Total TC | D16: Pass | E16: Fail | F16: Pass Rate | G16: Notes
B17: Login | C17: =COUNTIF(Test_Case!C8:C73, "Login") -> 12 | D17: =COUNTIFS(Test_Case!C8:C73, "Login", Test_Case!L8:L73, "PASS") -> 10 | E17: =COUNTIFS(Test_Case!C8:C73, "Login", Test_Case!L8:L73, "FAILS") -> 2 | F17: =D17/C17 -> 0.83333333 | G17: 2 security bugs: case-insensitive login, session not invalidated
B18: PIM | C18: =COUNTIF(Test_Case!C9:C74, "PIM") -> 15 | D18: =COUNTIFS(Test_Case!C9:C74, "PIM", Test_Case!L9:L74, "PASS") -> 14 | E18: =COUNTIFS(Test_Case!C9:C74, "PIM", Test_Case!L9:L74, "FAILS") -> 1 | F18: =D18/C18 -> 0.93333333 | G18: 1 bug: auto-generated Employee ID duplicates existing IDs
B19: Leave | C19: =COUNTIF(Test_Case!C10:C75, "Leave") -> 15 | D19: =COUNTIFS(Test_Case!C10:C75, "Leave", Test_Case!L10:L75, "PASS") -> 15 | E19: =COUNTIFS(Test_Case!C10:C75, "Leave", Test_Case!L10:L75, "FAILS") -> 0 | F19: =D19/C19 -> 1 | G19: All scenarios pass including boundary cases (weekend = 2 days)
B20: Directory | C20: =COUNTIF(Test_Case!C11:C76, "Directory") -> 8 | D20: =COUNTIFS(Test_Case!C11:C76, "Directory", Test_Case!L11:L76, "PASS") -> 8 | E20: =COUNTIFS(Test_Case!C11:C76, "Directory", Test_Case!L11:L76, "FAILS") -> 0 | F20: =D20/C20 -> 1 | G20: All pass — OBS-04 (filter inconsistency) could not be reproduced
B21: TOTAL | C21: =SUM(C17:C20) -> 50 | D21: =SUM(D17:D20) -> 47 | E21: =SUM(E17:E20) -> 3 | F21: =D21/C21 -> 0.94
A23: BUG REPORT SUMMARY
B24: Bug ID | C24: Module | D24: Severity | E24: Status | F24: TC Ref | G24: Title
B25: BUG-001 | C25: Login | D25: Medium | E25: Open | F25: TC_008 | G25: Username login is case-insensitive — 'ADMIN' accepted same as 'Admin'
B26: BUG-002 | C26: Login | D26: High | E26: Open | F26: TC_012 | G26: Session not invalidated after logout — Back button restores Dashboard access
B27: BUG-003 | C27: PIM | D27: Medium | E27: Open | F27: TC_016 | G27: Auto-generated Employee ID may duplicate existing IDs — no uniqueness check on generation
A29: PERSONAL NOTES & OBSERVATIONS (Tester's own words)
B30: Note 1: TC_028 — Leave Entitlement setup | C30: Ban đầu không hiểu tại sao ESS User không apply leave được — cứ nghĩ là bug. Sau 30 phút mới phát hiện phải assign Entitlement trước (TC_028). Đây là precondition quan trọng phải làm trước khi test toàn bộ Leave module.
B31: Note 2: TC_034 — Weekend calculation | C31: Assume lúc đầu: Thứ 6 → Thứ 2 = 4 ngày (tính cả Sat/Sun). Thực tế test ra = 2 ngày (chỉ working days). Phải sửa lại Expected Result. Bài học: không được assume behavior — phải test thật để biết.
B32: Note 3: TC_016 — Auto-generated Employee ID | C32: Phát hiện bug : hệ thống tự tạo Employee ID nhưng ID đó đã thuộc về người khác. Hệ thống báo lỗi khi save — không mất data. Nhưng UX tệ vì người dùng phải tự tìm ID trống để điền.
B33: Note 4: TC_008 — Case sensitivity | C33: ADMIN/admin123 đăng nhập được — hệ thống không phân biệt hoa/thường cho username. Đây là security weakness vì brute force dễ hơn. Log BUG-001. Ngược lại TC_009 " admin " với spaces bị reject — hệ thống nhạy cảm với spaces nhưng không nhạy cảm với case.
B34: Note 5: TC_012 — Session Bug | C34: Bug nghiêm trọng nhất: sau khi logout, bấm Back vẫn vào được Dashboard. Trong môi trường thật đây là lỗi bảo mật nguy hiểm — ai dùng máy chung có thể truy cập tài khoản người khác sau khi họ logout. Log BUG-002 với severity High.
A36: CONCLUSION & RECOMMENDATION
B37: Overall | C37: 94% pass rate (47/50 TC). Core HR workflows function correctly for both Admin and ESS User roles.
B38: Must Fix | C38: BUG-002 (High): Session invalidation — logout must fully clear session. Back button access is a security risk.
B39: Should Fix | C39: BUG-001 (Medium): Username should be case-sensitive. BUG-003 (Medium): Auto-generated Employee ID should be unique.
B40: Key Finding | C40: Leave module correctly calculates working days only — weekends excluded. Leave approval workflow functions end-to-end.
B41: Recommendation | C41: Conditionally approved — fix BUG-002 before production. Core functionality meets requirements.
